9.**Handling Bugs and Exceptions**
===  

## < *Contents* >
- [1. Handling Bugs](#%EF%B8%8F-1-handling-bugs)
- [2. Handling Exceptions](#%EF%B8%8F-2-handling-exceptions)


---

## ✔️ 1. **Handling Bugs**

### 1) **Cause of Software Bugs**
- 소프트웨어에서 버그(Bug)가 발생하는 원인은 크게 세 가지로 나눌 수 있다.
    - ① 논리적인 버그(ex. 알고리즘, 문법의 오용 등)
    - ② 실행 환경의 변화(ex. 컴퓨터, OS, 프로그래밍 언어 자체의 사양 변화)
    - ③ 오타  
- 이러한 이유로 발생하는 버그들은 **디버깅(Debugging)** 을 통해 잡아낼 수도 있지만, 아래와 같은 방법들을 사용하여 예방할 수도 있다.  

</br>

### 2) **Strict Mode**
- ECMAScript 5부터 추가된 **Strict 모드** 는 자바스크립트 언어의 사양 중에서 버그를 일으키기 쉬운 부분을 제거한다.
- 이는 버그를 최대한 발생하지 않게 만들거나, 버그가 발생했을 때 즉시 알릴 수 있도록 언어의 사양을 더욱 엄격하게 제한한다.  
- Strict 모드로 자바스크립트 프로그램을 실행하면 자바스크립트 엔진이 내부적으로 최적화 처리에 장애가 되는 부분을 제거하기 때문에, 몇몇 프로그램들은 Strict 모드로 실행했을 때 더 빠르게 실행되는 경우도 생긴다.  

</br>

- (1) **Strict 모드의 설정**
    - 프로그램을 Strict 모드로 실행하려면 스크립트 첫머리(모든 문장 앞에) 또는 함수의 첫머리(모든 문장 앞에) **"use strict";** 를 입력한다.
        ```javascript
        function f(x) {
            y = x;
            return y;
        }

        console.log(f(2)); // → 2 (정상 실행)
        ```
        ```javascript
        function g(x) {
            "use strict";
            y = x;
            return y;
        }

        console.log(g(2));  // → ReferenceError: y is not defined
        ```  

</br>

- (2) **Strict 모드를 설정하면 바뀌는 점**
    - ① 변수는 모두 선언해야 한다.  
    (선언되지 않은 변수, 함수, 함수의 인자에 값을 대입하면 ReferenceError가 발생한다.)  
    - ② 함수를 직접 호출할 때, 함수 안의 this 값이 undefined가 된다.  
    (비 Strict 모드에서는 함수 안의 this 값이 전역 객체의 참조가 된다.)
    - ③ with 문은 사용할 수 없다.
    - ④ 함수 정의문에 같은 이름의 인수가 있으면 문법 오류가 발생한다.
    - ⑤ 객체에 같은 이름의 프로퍼티가 있으면 문법 오류가 발생한다.
    - ⑥ NaN, Infinity, undefined를 표기하면 TypeError가 발생한다.
    - ⑦ arguments&#91;i&#93;는 호출되었을 때의 인수 값을 유지한다.  
    (비 Strict 모드에서는 arguments&#91;i&#93;가 인자의 별명이다. 따라서 한쪽을 수정하면 다른 쪽도 바뀐다.)
    - ⑧ arguments.callee를 읽을 수 없다.  
    (읽기를 시도하면 TypeError가 발생한다.)
    - ⑨ eval로 실행한 코드는 호출자의 유효 범위 안에 새로운 변수나 함수를 선언할 수 없다.  

</br>

### 3) **Style Guide**
- 프로그램을 작성할 때 버그를 피하고, 가독성을 높이기 위한 코딩 규칙을 정리한 것을 **스타일 가이드(Style Guide)** 라고 한다.  
- 자바스크립트의 대표적인 스타일 가이드는 다음과 같다.
    - [Google JavaScript Style Guide](https://google.github.io/styleguide/jsguide.html)
    - [jQuery Javascript Style Guide](https://contribute.jquery.org/style-guide/js/)
    - [Airbnb Javascript Style Guide](https://github.com/airbnb/javascript)
    - [MDN Docs Javascript Style Guide](https://developer.mozilla.org/en-US/docs/MDN/Writing_guidelines/Writing_style_guide/Code_style_guide/JavaScript)  

</br>

## ✔️ 2. **Handling Exceptions**  


### 1) **Exception(예외)**
- **예외(Exception)** 란 프로그램 실행 중에 발생하는 런타임 에러를 의미한다.
- 예외 발생 시, 자바스크립트에서는 예외를 **throw** 하여 해당 예외를 통지한 후, 이를 받아서 처리(handle)한다.  
(여기서 던지는 예외는 오류 및 예외 조건이 발생한 사실을 알려주는 일종의 신호이다.)
- 이때, 예외를 **catch** 하여(받아) 처리하는 부분을 가리켜 **예외 처리기(Exception Handler)** 라고 한다.  
- 자바스크립트에서는 **throw** 문으로 예외를 던지고, **try/catch/finally** 문으로 예외를 잡아서 처리한다.  

</br>

### 2) **throw 문**  
- **throw** 문은 예외를 던지는 역할을 한다.
    ```javascript
    throw 표현식
    ```  
- throw 문에서 표현식에는 모든 타입의 값을 지정해줄 수 있는데, 일반적으로는 **Error 객체** 나 이를 상속한 객체를 지정한다.
    ```javascript
    /* 배열을 받아 요소들의 총합을 반환하는 메소드 */
    function getSumOfArr(arr) {
        // 인자가 Array 타입의 인스턴스가 아닐 경우 예외를 throw 한다.
        if (!(arr instanceof Array)) {
            throw new Error(arr + "is not an array");
        }
        ...
    }
    ```  

</br>

### 3) **Error Object**
- 자바스크립트에는 예외를 표현하기 위한 다음과 같은 내장 객체들이 준비되어 있다.
    <table border="1">
        <tr>
            <th><center>생성자</center></th>
            <th><center>생성하는 인스턴스</center></th>
        </tr>
        <tr>
            <td align="center">Error</td>
            <td>범용적인 예외 객체</td>
        </tr>
        <tr>
            <td align="center">EvalError</td>
            <td>eval 함수와 관련해서 발생한 예외 객체</td>
        </tr>
        <tr>
            <td align="center">RangeError</td>
            <td>숫자 값이 허용 범위를 벗어났을 때 발생하는 예외 객체</td>
        </tr>
        <tr>
            <td align="center">ReferenceError</td>
            <td>잘못된 참조를 만났을 때 발생하는 예외 객체</td>
        </tr>
        <tr>
            <td align="center">SyntaxError</td>
            <td>자바스크립트 문법에 어긋나는 구문을 만났을 때 발생하는 예외 객체</td>
        </tr>
        <tr>
            <td align="center">TypeError</td>
            <td>변수 및 인수 타입이 유효하지 않을 때 발생하는 예외 객체</td>
        </tr>
        <tr>
            <td align="center">URIError</td>
            <td>encodeURI와 decodeURI 메소드에 잘못된 인수가 전달되었을 때 발생하는 예외 객체</td>
        </tr>
    </table>  

    ```javascript
    x++;                      // ReferenceError : 없는 변수 x를 만남

    if (a > 0) { a > 0;       // SyntaxError : '}' 가 존재하지 않음

    const obj = {};
    obj.join();               // TypeError : join 메소드가 정의되어 있지 않음
    
    let pi = 3.14159;
    pi.toFixed(100);          // RangeError : toFixed 메소드는 0 ~ 20 사이의 값만 받을 수 있음

    decodeURIComponent("%");  // URIError : % 이후에 아무것도 없음

    // ※ 현재는 더 이상 EvalError가 발생하지 않지만, 하위 호환성을 위해 남아있다.
    ```  

    </br>

- 예외를 표현하는 모든 내장 객체는 Error.prototype의 프로퍼티와 메소드를 상속받는다.
    - message : 오류 메시지를 뜻하는 문자열
    - name : 오류 이름을 뜻하는 문자열
    - toString() : 지정된 객체를 표현하는 문자열을 반환하는 메소드 
    ```javascript
    const error = new TypeError("Not an Array.");
    console.log(error.message);     // → Not an Array.
    console.log(error.name);        // → TypeError
    console.log(error.toString());  // → TypeError: Not an Array.
    ```  

</br>  

### 4) **try/catch/finally**
- **try/catch/finally** 문은 예외가 던져졌을(throw) 때 해당 예외를 잡아서(catch) 처리(handle)하는 역할을 한다.  
    ```javascript
    try {
        /* 예외가 발생할 수 있는 코드 */
    } catch(exception) {
        /*
         * try 블록에서 예외가 발생했을 때 실행할 코드
         * exception에는 던져진 예외 값(Error 객체)이 들어온다.
         * 해당 값을 바탕으로 예외를 처리한다.
         */
    } finally {
        /* try, catch 블록 코드가 실행된 이후에 '반드시' 실행되는 코드 */
    }
    ```  
    ```javascript
    try {
        let sum = getSumOfArr(object);  // 예외를 던질 가능성이 있는 함수
        console.log("Sum of Array : " + sum);
    } catch(e) {
        alert(e);
    } finally {
        console.log("Error!")
    }
    ```  

</br>

- 예외가 여러 개 발생할 경우, 다음과 같이 catch 블록 안에서 예외를 유형별로 처리해주어야 한다.
- 이런 상황에서는 다음과 같이 instanceof 연산자로 예외 타입을 판별할 수 있다.
    ```javascript
    try {
        // 이 지점에서 오류가 발생한다고 가정한다.
    } catch(e) {
        if (e instanceof TypeError) {
            // TypeError가 발생했을 때의 처리를 작성한다.
        } else if (e instanceof ReferenceError) {
            // ReferenceError가 발생했을 때의 처리를 작성한다.
        } else {
            // 그 외의 예외가 발생했을 때의 처리를 작성한다.
        }
    }
    ```  

</br>

### 5) **Exception Propagation**
- 자바스크립트에서 예외는 호출 스택(Call stack)을 거슬러 올라가며 전파(Propagate)된다.
- 아래 예시에서 발생한 예외는 'h → g → f → 전역 코드' 순서대로 호출 스택을 거슬러 올라가며 전파된다.
- 해당 예외는 최종적으로 전역 코드의 try/catch 문에 걸려서 처리된다.  
- 만약 호출 스택 내에서 예외 처리기를 찾지 못하면 프로그램이 강제 종료되며, 예외는 사용자 오류로 보고된다.  
- 이러한 특성을 사용하여 예외를 상위 메소드에 위임(delegate)하여 처리할 수 있다.
    ```javascript
    try {
        f();
    } catch(e) {
        console.log(e.name + " has occurred : " + e.message);
        // → SyntaxError has occurred : 문법 오류가 발생했습니다.
    }

    function f() { g(); }
    function g() { h(); };
    function h() { 
        console.log(this.callee);
        throw new SyntaxError("문법 오류가 발생했습니다.");
    }
    ```  

</br>

- 단, 비동기 처리의 콜백 함수가 던진 예외는 콜백 함수를 넘긴 함수로 전파되지 않는다.  
- 따라서 비동기 처리 과정에서 콜백 함수가 던진 예외는 감지되지 않으며, 프로그램이 종료되어 버린다.
    ```javascript
    try {
        setTimeout(function throwError() {
            throw new Error("Exception has occurred.");
        }, 1000);
    } catch(e) {
        console.log(e.name + " has occurred : " + e.message);
        // →
    }
    ```
    ```
    c:\Users\OOO\OOOOO\Web_Development\Javascript\OOO.js:3
            throw new Error("Timeout Exception");
            ^

    Error: Timeout Exception
        at Timeout.throwError [as _onTimeout]   
        (c:\Users\OOO\OOOOO\Web Development\Javascript\OOO.js:3:15)
        at listOnTimeout (node:internal/timers:559:17)
        at processTimers (node:internal/timers:502:7)
    ```  
- 이는 예외를 던지는 콜백 함수 throwError는 함수 정의가 try 블록 안에 있을 뿐, try 블록 안에서 호출된 것이 아니기 때문이다.  
- 이 콜백 함수를 호출한 주체는 타이머 이벤트이며, try 블록 안에서 발생한 예외가 아니기 때문에 해당 예외를 잡을 수가 없는 것이다.  
- 위와 같은 문제는 이벤트 처리기 함수를 등록할 때나, Ajax로 Web API를 요청할 때도 발생한다.   

</br>

- ECMAScript 6부터 추가된 제너레이터(Generator)를 활용하면 이와 같이 비동기 처리 중에 발생한 예외를 잡을 수 있다.  
    ```javascript
    /*
    * 테스트용 함수
    * (첫 번째 인수로 제너레이터의 참조가 필요하다.)
    */
    function sleepAndError(g, n) {
        setTimeout(function() {
            for (let i = 0; i < n; i++) console.log(i);  // do something
            g.throw(new Error("오류가 발생했습니다."));
        }, 1000);
    }

    /* 
    * callback 함수를 실행하는 함수
    * (call back 함수가 비동기 처리 중에 발생시킨 예외도 잡아서 처리한다.)
    */
    function run(callback, ...argsList) {
        const g = (function* (cb, args) {
            try {
                yield cb(g, ...args);
            } catch(e) {
                console.log("예외를 잡음 → " + e);
            }
        })(callback, argsList);
        g.next();
    }

    run(sleepAndError, 10);
    ```  
    ```
    0
    1
    2
    3
    4
    5
    6
    7
    8
    9
    예외를 잡음 → Error: 오류가 발생했습니다.
    ```  
- 위의 코드에서 sleepAndError 함수가 예외를 던질 때 그 예외를 throw 문이 아니라 첫 번째 인수로 받은 제너레이터 객체 g의 throw 메소드에 던지는 부분이 중요하다.  
- 제너레이터 객체 g의 throw 메소드는 호출된 그 자리에서 예외를 던지는 것이 아니라, 제너레이터를 한 번 동작시킨 다음에 yield 문이 위치한 자리에서 예외를 던진다.
- 그러면 이 예외는 제너레이터가 던진 예외가 되므로, catch 블록 안에서 잡아 처리할 수 있게 된다.  
